Workbook
Name Set_FollowUpDays: Settings!$E$5
Name Set_DueSoonDays: Settings!$E$6
Name Set_InterviewWindow: Settings!$E$7
Name Set_MinSample: Settings!$E$8
Name App_ID: 'Applications'!$A$5:$A$1004
Name App_DateApplied: 'Applications'!$C$5:$C$1004
Name App_Company: 'Applications'!$D$5:$D$1004
Name App_JobTitle: 'Applications'!$E$5:$E$1004
Name App_URL: 'Applications'!$I$5:$I$1004
Name App_Source: 'Applications'!$J$5:$J$1004
Name App_Priority: 'Applications'!$K$5:$K$1004
Name App_Match: 'Applications'!$L$5:$L$1004
Name App_Status: 'Applications'!$M$5:$M$1004
Name App_NextAction: 'Applications'!$N$5:$N$1004
Name App_NextDate: 'Applications'!$O$5:$O$1004
Name App_Contact: 'Applications'!$P$5:$P$1004
Name App_CV: 'Applications'!$R$5:$R$1004
Name App_Skills: 'Applications'!$V$5:$V$1004
Name App_Role: 'Applications'!$Z$5:$Z$1004
Name App_RespDate: 'Applications'!$AA$5:$AA$1004
Name App_Flag: 'Applications'!$AC$5:$AC$1004
Name App_MatchCat: 'Applications'!$AD$5:$AD$1004
Name App_Furthest: 'Applications'!$AE$5:$AE$1004
Name App_DaysToResp: 'Applications'!$AF$5:$AF$1004
Name App_Stage: 'Applications'!$AG$5:$AG$1004
Name App_ActionKey: 'Applications'!$AH$5:$AH$1004
Name App_ActiveKey: 'Applications'!$AI$5:$AI$1004
Name Int_Company: 'Interviews'!$A$5:$A$304
Name Int_JobTitle: 'Interviews'!$B$5:$B$304
Name Int_Stage: 'Interviews'!$C$5:$C$304
Name Int_Date: 'Interviews'!$D$5:$D$304
Name Int_Interviewer: 'Interviews'!$E$5:$E$304
Name Int_Type: 'Interviews'!$F$5:$F$304
Name Int_Prep: 'Interviews'!$G$5:$G$304
Name Int_NextStep: 'Interviews'!$L$5:$L$304
Name Int_Key: 'Interviews'!$O$5:$O$304
Name Co_Company: 'Companies'!$A$5:$A$304
Name Ct_Name: 'Contacts'!$A$5:$A$504
Name Ct_Company: 'Contacts'!$B$5:$B$504
Name Ct_JobTitle: 'Contacts'!$C$5:$C$504
Name Ct_LinkedIn: 'Contacts'!$D$5:$D$504
Name Ct_Relationship: 'Contacts'!$F$5:$F$504
Name Ct_Contacted: 'Contacts'!$G$5:$G$504
Name Ct_Response: 'Contacts'!$I$5:$I$504
Name Ct_FollowUp: 'Contacts'!$J$5:$J$504
Name Ct_RefPotential: 'Contacts'!$K$5:$K$504
Name Ct_Notes: 'Contacts'!$L$5:$L$504
Name Ct_Key: 'Contacts'!$M$5:$M$504

Sheet Job Search Dashboard
B1: Job Search Dashboard | I1: As of | J1: =TODAY()
B2: AI Engineer · Generative AI · Agentic AI · AI Automation · AI Solutions — Stuttgart region, Germany & remote
B4: OVERVIEW
B5: Total Applications | D5: Applications This Week | G5: Applications This Month | I5: Active Applications
B6: =COUNTIFS(App_Stage,">=1") | D6: =COUNTIFS(App_DateApplied,">="&(TODAY()-WEEKDAY(TODAY(),2)+1),App_DateApplied,"<"&(TODAY()-WEEKDAY(TODAY(),2)+8)) | G6: =COUNTIFS(App_DateApplied,">="&DATE(YEAR(TODAY()),MONTH(TODAY()),1),App_DateApplied,"<"&(EOMONTH(TODAY(),0)+1)) | I6: =COUNTIFS(App_Stage,">=1",App_Stage,"<=6",App_Status,"<>Rejected",App_Status,"<>Withdrawn")
B7: submitted (beyond Wishlist) | D7: Mon–Sun, by Date Applied | G7: calendar month, by Date Applied | I7: Applied → Offer, still open
B9: Interviews | D9: Final Rounds | G9: Offers | I9: Accepted
B10: =COUNTIFS(App_Stage,">=3") | D10: =COUNTIFS(App_Stage,">=5") | G10: =COUNTIFS(App_Stage,">=6") | I10: =COUNTIF(App_Status,"Accepted")
B11: reached Interview 1 or later | D11: reached the final round | G11: offers received | I11: offers accepted
B13: =IF($M$13=0,"✓ Nothing due — all follow-ups are on track.","Today: "&'Follow-Ups'!$B$6&" overdue · "&'Follow-Ups'!$C$6&" due today · "&'Follow-Ups'!$D$6&" no response · "&'Follow-Ups'!$E$6&" due soon · "&'Follow-Ups'!$F$6&" contact follow-ups · "&'Follow-Ups'!$G$6&" upcoming interviews → Follow-Ups tab") | L13: ='Follow-Ups'!$B$6 | M13: =SUM('Follow-Ups'!$B$6:$G$6)
B15: PIPELINE · CURRENT STATUS | G15: CONVERSION
B16: Status | D16: Count | G16: Metric | I16: Rate | J16: Basis
B17: Wishlist | D17: =COUNTIF(App_Status,$B17) | E17: =IF(OR(NOT(ISNUMBER(D17)),MAX($D$17:$D$26)<=0),"",IF(D17<=0,"",REPT("█",MAX(1,ROUND(D17/MAX($D$17:$D$26)*14,0))))) | G17: Application → Interview | I17: =IF(B6=0,"–",B10/B6) | J17: =B10&" of "&B6
B18: Applied | D18: =COUNTIF(App_Status,$B18) | E18: =IF(OR(NOT(ISNUMBER(D18)),MAX($D$17:$D$26)<=0),"",IF(D18<=0,"",REPT("█",MAX(1,ROUND(D18/MAX($D$17:$D$26)*14,0))))) | G18: Interview → Final | I18: =IF(B10=0,"–",D10/B10) | J18: =D10&" of "&B10
B19: Screening | D19: =COUNTIF(App_Status,$B19) | E19: =IF(OR(NOT(ISNUMBER(D19)),MAX($D$17:$D$26)<=0),"",IF(D19<=0,"",REPT("█",MAX(1,ROUND(D19/MAX($D$17:$D$26)*14,0))))) | G19: Final → Offer | I19: =IF(D10=0,"–",G10/D10) | J19: =G10&" of "&D10
B20: Interview 1 | D20: =COUNTIF(App_Status,$B20) | E20: =IF(OR(NOT(ISNUMBER(D20)),MAX($D$17:$D$26)<=0),"",IF(D20<=0,"",REPT("█",MAX(1,ROUND(D20/MAX($D$17:$D$26)*14,0))))) | G20: Overall Offer Rate | I20: =IF(B6=0,"–",G10/B6) | J20: =G10&" of "&B6
B21: Interview 2 | D21: =COUNTIF(App_Status,$B21) | E21: =IF(OR(NOT(ISNUMBER(D21)),MAX($D$17:$D$26)<=0),"",IF(D21<=0,"",REPT("█",MAX(1,ROUND(D21/MAX($D$17:$D$26)*14,0))))) | G21: Avg. Days to First Response | I21: =IF(COUNT(App_DaysToResp)=0,"–",AVERAGE(App_DaysToResp)) | J21: ="from "&COUNT(App_DaysToResp)&" replies"
B22: Final | D22: =COUNTIF(App_Status,$B22) | E22: =IF(OR(NOT(ISNUMBER(D22)),MAX($D$17:$D$26)<=0),"",IF(D22<=0,"",REPT("█",MAX(1,ROUND(D22/MAX($D$17:$D$26)*14,0)))))
B23: Offer | D23: =COUNTIF(App_Status,$B23) | E23: =IF(OR(NOT(ISNUMBER(D23)),MAX($D$17:$D$26)<=0),"",IF(D23<=0,"",REPT("█",MAX(1,ROUND(D23/MAX($D$17:$D$26)*14,0))))) | G23: DATA CHECKS
B24: Accepted | D24: =COUNTIF(App_Status,$B24) | E24: =IF(OR(NOT(ISNUMBER(D24)),MAX($D$17:$D$26)<=0),"",IF(D24<=0,"",REPT("█",MAX(1,ROUND(D24/MAX($D$17:$D$26)*14,0))))) | G24: Submitted, but no Date Applied | I24: =SUMPRODUCT(ISNUMBER(App_Stage)*(App_Stage>=1)*NOT(ISNUMBER(App_DateApplied))) | J24: =IF(I24=0,"✓ ok","⚠ fix on Applications")
B25: Rejected | D25: =COUNTIF(App_Status,$B25) | E25: =IF(OR(NOT(ISNUMBER(D25)),MAX($D$17:$D$26)<=0),"",IF(D25<=0,"",REPT("█",MAX(1,ROUND(D25/MAX($D$17:$D$26)*14,0))))) | G25: Submitted, but no Role Category | I25: =SUMPRODUCT(ISNUMBER(App_Stage)*(App_Stage>=1)*(App_Role="")) | J25: =IF(I25=0,"✓ ok","⚠ fix on Applications")
B26: Withdrawn | D26: =COUNTIF(App_Status,$B26) | E26: =IF(OR(NOT(ISNUMBER(D26)),MAX($D$17:$D$26)<=0),"",IF(D26<=0,"",REPT("█",MAX(1,ROUND(D26/MAX($D$17:$D$26)*14,0))))) | G26: Duplicate Application IDs | I26: =SUMPRODUCT(ISNUMBER(App_ID)*(COUNTIF(App_ID,App_ID)>1)) | J26: =IF(I26=0,"✓ ok","⚠ fix on Applications")
B28: APPLICATIONS BY ROLE | G28: APPLICATIONS BY SOURCE
D29: Apps | I29: Apps
B30: =Settings!$J$13 | D30: =COUNTIFS(App_Role,$B30,App_Stage,">=1") | E30: =IF(OR(NOT(ISNUMBER(D30)),MAX($D$30:$D$41)<=0),"",IF(D30<=0,"",REPT("█",MAX(1,ROUND(D30/MAX($D$30:$D$41)*14,0))))) | G30: =Settings!$D$13 | I30: =COUNTIFS(App_Source,$G30,App_Stage,">=1") | J30: =IF(OR(NOT(ISNUMBER(I30)),MAX($I$30:$I$40)<=0),"",IF(I30<=0,"",REPT("█",MAX(1,ROUND(I30/MAX($I$30:$I$40)*14,0)))))
B31: =Settings!$J$14 | D31: =COUNTIFS(App_Role,$B31,App_Stage,">=1") | E31: =IF(OR(NOT(ISNUMBER(D31)),MAX($D$30:$D$41)<=0),"",IF(D31<=0,"",REPT("█",MAX(1,ROUND(D31/MAX($D$30:$D$41)*14,0))))) | G31: =Settings!$D$14 | I31: =COUNTIFS(App_Source,$G31,App_Stage,">=1") | J31: =IF(OR(NOT(ISNUMBER(I31)),MAX($I$30:$I$40)<=0),"",IF(I31<=0,"",REPT("█",MAX(1,ROUND(I31/MAX($I$30:$I$40)*14,0)))))
B32: =Settings!$J$15 | D32: =COUNTIFS(App_Role,$B32,App_Stage,">=1") | E32: =IF(OR(NOT(ISNUMBER(D32)),MAX($D$30:$D$41)<=0),"",IF(D32<=0,"",REPT("█",MAX(1,ROUND(D32/MAX($D$30:$D$41)*14,0))))) | G32: =Settings!$D$15 | I32: =COUNTIFS(App_Source,$G32,App_Stage,">=1") | J32: =IF(OR(NOT(ISNUMBER(I32)),MAX($I$30:$I$40)<=0),"",IF(I32<=0,"",REPT("█",MAX(1,ROUND(I32/MAX($I$30:$I$40)*14,0)))))
B33: =Settings!$J$16 | D33: =COUNTIFS(App_Role,$B33,App_Stage,">=1") | E33: =IF(OR(NOT(ISNUMBER(D33)),MAX($D$30:$D$41)<=0),"",IF(D33<=0,"",REPT("█",MAX(1,ROUND(D33/MAX($D$30:$D$41)*14,0))))) | G33: =Settings!$D$16 | I33: =COUNTIFS(App_Source,$G33,App_Stage,">=1") | J33: =IF(OR(NOT(ISNUMBER(I33)),MAX($I$30:$I$40)<=0),"",IF(I33<=0,"",REPT("█",MAX(1,ROUND(I33/MAX($I$30:$I$40)*14,0)))))
B34: =Settings!$J$17 | D34: =COUNTIFS(App_Role,$B34,App_Stage,">=1") | E34: =IF(OR(NOT(ISNUMBER(D34)),MAX($D$30:$D$41)<=0),"",IF(D34<=0,"",REPT("█",MAX(1,ROUND(D34/MAX($D$30:$D$41)*14,0))))) | G34: =Settings!$D$17 | I34: =COUNTIFS(App_Source,$G34,App_Stage,">=1") | J34: =IF(OR(NOT(ISNUMBER(I34)),MAX($I$30:$I$40)<=0),"",IF(I34<=0,"",REPT("█",MAX(1,ROUND(I34/MAX($I$30:$I$40)*14,0)))))
B35: =Settings!$J$18 | D35: =COUNTIFS(App_Role,$B35,App_Stage,">=1") | E35: =IF(OR(NOT(ISNUMBER(D35)),MAX($D$30:$D$41)<=0),"",IF(D35<=0,"",REPT("█",MAX(1,ROUND(D35/MAX($D$30:$D$41)*14,0))))) | G35: =Settings!$D$18 | I35: =COUNTIFS(App_Source,$G35,App_Stage,">=1") | J35: =IF(OR(NOT(ISNUMBER(I35)),MAX($I$30:$I$40)<=0),"",IF(I35<=0,"",REPT("█",MAX(1,ROUND(I35/MAX($I$30:$I$40)*14,0)))))
B36: =Settings!$J$19 | D36: =COUNTIFS(App_Role,$B36,App_Stage,">=1") | E36: =IF(OR(NOT(ISNUMBER(D36)),MAX($D$30:$D$41)<=0),"",IF(D36<=0,"",REPT("█",MAX(1,ROUND(D36/MAX($D$30:$D$41)*14,0))))) | G36: =Settings!$D$19 | I36: =COUNTIFS(App_Source,$G36,App_Stage,">=1") | J36: =IF(OR(NOT(ISNUMBER(I36)),MAX($I$30:$I$40)<=0),"",IF(I36<=0,"",REPT("█",MAX(1,ROUND(I36/MAX($I$30:$I$40)*14,0)))))
B37: =Settings!$J$20 | D37: =COUNTIFS(App_Role,$B37,App_Stage,">=1") | E37: =IF(OR(NOT(ISNUMBER(D37)),MAX($D$30:$D$41)<=0),"",IF(D37<=0,"",REPT("█",MAX(1,ROUND(D37/MAX($D$30:$D$41)*14,0))))) | G37: =Settings!$D$20 | I37: =COUNTIFS(App_Source,$G37,App_Stage,">=1") | J37: =IF(OR(NOT(ISNUMBER(I37)),MAX($I$30:$I$40)<=0),"",IF(I37<=0,"",REPT("█",MAX(1,ROUND(I37/MAX($I$30:$I$40)*14,0)))))
B38: =Settings!$J$21 | D38: =COUNTIFS(App_Role,$B38,App_Stage,">=1") | E38: =IF(OR(NOT(ISNUMBER(D38)),MAX($D$30:$D$41)<=0),"",IF(D38<=0,"",REPT("█",MAX(1,ROUND(D38/MAX($D$30:$D$41)*14,0))))) | G38: =Settings!$D$21 | I38: =COUNTIFS(App_Source,$G38,App_Stage,">=1") | J38: =IF(OR(NOT(ISNUMBER(I38)),MAX($I$30:$I$40)<=0),"",IF(I38<=0,"",REPT("█",MAX(1,ROUND(I38/MAX($I$30:$I$40)*14,0)))))
B39: =Settings!$J$22 | D39: =COUNTIFS(App_Role,$B39,App_Stage,">=1") | E39: =IF(OR(NOT(ISNUMBER(D39)),MAX($D$30:$D$41)<=0),"",IF(D39<=0,"",REPT("█",MAX(1,ROUND(D39/MAX($D$30:$D$41)*14,0))))) | G39: =Settings!$D$22 | I39: =COUNTIFS(App_Source,$G39,App_Stage,">=1") | J39: =IF(OR(NOT(ISNUMBER(I39)),MAX($I$30:$I$40)<=0),"",IF(I39<=0,"",REPT("█",MAX(1,ROUND(I39/MAX($I$30:$I$40)*14,0)))))
B40: =Settings!$J$23 | D40: =COUNTIFS(App_Role,$B40,App_Stage,">=1") | E40: =IF(OR(NOT(ISNUMBER(D40)),MAX($D$30:$D$41)<=0),"",IF(D40<=0,"",REPT("█",MAX(1,ROUND(D40/MAX($D$30:$D$41)*14,0))))) | G40: Not set | I40: =MAX(0,B6-SUM(I30:I39)) | J40: =IF(OR(NOT(ISNUMBER(I40)),MAX($I$30:$I$40)<=0),"",IF(I40<=0,"",REPT("█",MAX(1,ROUND(I40/MAX($I$30:$I$40)*14,0)))))
B41: Not set | D41: =MAX(0,B6-SUM(D30:D40)) | E41: =IF(OR(NOT(ISNUMBER(D41)),MAX($D$30:$D$41)<=0),"",IF(D41<=0,"",REPT("█",MAX(1,ROUND(D41/MAX($D$30:$D$41)*14,0)))))
B43: MATCH QUALITY · YOUR OWN ASSESSMENT | G43: TOP PERFORMERS · INTERVIEW RATE
D44: Apps
B45: Excellent Match · 90–100% | D45: =COUNTIFS(App_MatchCat,"Excellent Match",App_Stage,">=1") | E45: =IF(OR(NOT(ISNUMBER(D45)),MAX($D$45:$D$49)<=0),"",IF(D45<=0,"",REPT("█",MAX(1,ROUND(D45/MAX($D$45:$D$49)*14,0))))) | G45: CV version | H45: =Analytics!C23
B46: Strong Match · 75–89% | D46: =COUNTIFS(App_MatchCat,"Strong Match",App_Stage,">=1") | E46: =IF(OR(NOT(ISNUMBER(D46)),MAX($D$45:$D$49)<=0),"",IF(D46<=0,"",REPT("█",MAX(1,ROUND(D46/MAX($D$45:$D$49)*14,0))))) | G46: Source | H46: =Analytics!C56
...

Sheet Follow-Ups
B1: Follow-Ups
B2: Everything that needs your attention, most urgent first. Fills itself from Applications, Contacts and Interviews.
B3: ="No-response threshold: "&Set_FollowUpDays&" days · Due-soon window: "&Set_DueSoonDays&" days · Upcoming interviews: next "&Set_InterviewWindow&" days · change these on Settings"
B5: Follow Up Required | C5: Action Due Today | D5: No Response Yet | E5: Due Soon | F5: Contact Follow-ups | G5: Upcoming Interviews
B6: =COUNTIF(App_Flag,"FOLLOW UP REQUIRED") | C6: =COUNTIF(App_Flag,"ACTION DUE TODAY") | D6: =COUNTIF(App_Flag,"NO RESPONSE") | E6: =COUNTIF(App_Flag,"DUE SOON") | F6: =COUNT(Ct_Key) | G6: =COUNT(Int_Key)
B8: APPLICATIONS — ACTION LIST (OVERDUE FIRST, THEN DUE TODAY, NO RESPONSE, DUE SOON)
B9: Action Flag | C9: Company | D9: Job Title | E9: Status | F9: Next Action | G9: Next Action Date | H9: Days Overdue | I9: Date Applied | J9: Days Since Applied | K9: Priority | L9: Recruiter / Hiring Manager | M9: Job Link
B10: =IF($N10="","",INDEX(App_Flag,$N10)&"") | C10: =IF($N10="","",INDEX(App_Company,$N10)&"") | D10: =IF($N10="","",INDEX(App_JobTitle,$N10)&"") | E10: =IF($N10="","",INDEX(App_Status,$N10)&"") | F10: =IF($N10="","",INDEX(App_NextAction,$N10)&"") | G10: =IF($N10="","",IF(ISNUMBER(INDEX(App_NextDate,$N10)),INDEX(App_NextDate,$N10),"")) | H10: =IF($N10="","",IF(ISNUMBER(INDEX(App_NextDate,$N10)),IF(INT(INDEX(App_NextDate,$N10))<TODAY(),TODAY()-INT(INDEX(App_NextDate,$N10)),""),"")) | I10: =IF($N10="","",IF(ISNUMBER(INDEX(App_DateApplied,$N10)),INDEX(App_DateApplied,$N10),"")) | J10: =IF($N10="","",IF(ISNUMBER(INDEX(App_DateApplied,$N10)),TODAY()-INT(INDEX(App_DateApplied,$N10)),"")) | K10: =IF($N10="","",INDEX(App_Priority,$N10)&"") | L10: =IF($N10="","",INDEX(App_Contact,$N10)&"") | M10: =IF($N10="","",IF(INDEX(App_URL,$N10)="","",HYPERLINK(INDEX(App_URL,$N10),"Open ↗"))) | N10: =IFERROR(MATCH(SMALL(App_ActionKey,1),App_ActionKey,0),"")
B11: =IF($N11="","",INDEX(App_Flag,$N11)&"") | C11: =IF($N11="","",INDEX(App_Company,$N11)&"") | D11: =IF($N11="","",INDEX(App_JobTitle,$N11)&"") | E11: =IF($N11="","",INDEX(App_Status,$N11)&"") | F11: =IF($N11="","",INDEX(App_NextAction,$N11)&"") | G11: =IF($N11="","",IF(ISNUMBER(INDEX(App_NextDate,$N11)),INDEX(App_NextDate,$N11),"")) | H11: =IF($N11="","",IF(ISNUMBER(INDEX(App_NextDate,$N11)),IF(INT(INDEX(App_NextDate,$N11))<TODAY(),TODAY()-INT(INDEX(App_NextDate,$N11)),""),"")) | I11: =IF($N11="","",IF(ISNUMBER(INDEX(App_DateApplied,$N11)),INDEX(App_DateApplied,$N11),"")) | J11: =IF($N11="","",IF(ISNUMBER(INDEX(App_DateApplied,$N11)),TODAY()-INT(INDEX(App_DateApplied,$N11)),"")) | K11: =IF($N11="","",INDEX(App_Priority,$N11)&"") | L11: =IF($N11="","",INDEX(App_Contact,$N11)&"") | M11: =IF($N11="","",IF(INDEX(App_URL,$N11)="","",HYPERLINK(INDEX(App_URL,$N11),"Open ↗"))) | N11: =IFERROR(MATCH(SMALL(App_ActionKey,2),App_ActionKey,0),"")
B12: =IF($N12="","",INDEX(App_Flag,$N12)&"") | C12: =IF($N12="","",INDEX(App_Company,$N12)&"") | D12: =IF($N12="","",INDEX(App_JobTitle,$N12)&"") | E12: =IF($N12="","",INDEX(App_Status,$N12)&"") | F12: =IF($N12="","",INDEX(App_NextAction,$N12)&"") | G12: =IF($N12="","",IF(ISNUMBER(INDEX(App_NextDate,$N12)),INDEX(App_NextDate,$N12),"")) | H12: =IF($N12="","",IF(ISNUMBER(INDEX(App_NextDate,$N12)),IF(INT(INDEX(App_NextDate,$N12))<TODAY(),TODAY()-INT(INDEX(App_NextDate,$N12)),""),"")) | I12: =IF($N12="","",IF(ISNUMBER(INDEX(App_DateApplied,$N12)),INDEX(App_DateApplied,$N12),"")) | J12: =IF($N12="","",IF(ISNUMBER(INDEX(App_DateApplied,$N12)),TODAY()-INT(INDEX(App_DateApplied,$N12)),"")) | K12: =IF($N12="","",INDEX(App_Priority,$N12)&"") | L12: =IF($N12="","",INDEX(App_Contact,$N12)&"") | M12: =IF($N12="","",IF(INDEX(App_URL,$N12)="","",HYPERLINK(INDEX(App_URL,$N12),"Open ↗"))) | N12: =IFERROR(MATCH(SMALL(App_ActionKey,3),App_ActionKey,0),"")
B13: =IF($N13="","",INDEX(App_Flag,$N13)&"") | C13: =IF($N13="","",INDEX(App_Company,$N13)&"") | D13: =IF($N13="","",INDEX(App_JobTitle,$N13)&"") | E13: =IF($N13="","",INDEX(App_Status,$N13)&"") | F13: =IF($N13="","",INDEX(App_NextAction,$N13)&"") | G13: =IF($N13="","",IF(ISNUMBER(INDEX(App_NextDate,$N13)),INDEX(App_NextDate,$N13),"")) | H13: =IF($N13="","",IF(ISNUMBER(INDEX(App_NextDate,$N13)),IF(INT(INDEX(App_NextDate,$N13))<TODAY(),TODAY()-INT(INDEX(App_NextDate,$N13)),""),"")) | I13: =IF($N13="","",IF(ISNUMBER(INDEX(App_DateApplied,$N13)),INDEX(App_DateApplied,$N13),"")) | J13: =IF($N13="","",IF(ISNUMBER(INDEX(App_DateApplied,$N13)),TODAY()-INT(INDEX(App_DateApplied,$N13)),"")) | K13: =IF($N13="","",INDEX(App_Priority,$N13)&"") | L13: =IF($N13="","",INDEX(App_Contact,$N13)&"") | M13: =IF($N13="","",IF(INDEX(App_URL,$N13)="","",HYPERLINK(INDEX(App_URL,$N13),"Open ↗"))) | N13: =IFERROR(MATCH(SMALL(App_ActionKey,4),App_ActionKey,0),"")
B14: =IF($N14="","",INDEX(App_Flag,$N14)&"") | C14: =IF($N14="","",INDEX(App_Company,$N14)&"") | D14: =IF($N14="","",INDEX(App_JobTitle,$N14)&"") | E14: =IF($N14="","",INDEX(App_Status,$N14)&"") | F14: =IF($N14="","",INDEX(App_NextAction,$N14)&"") | G14: =IF($N14="","",IF(ISNUMBER(INDEX(App_NextDate,$N14)),INDEX(App_NextDate,$N14),"")) | H14: =IF($N14="","",IF(ISNUMBER(INDEX(App_NextDate,$N14)),IF(INT(INDEX(App_NextDate,$N14))<TODAY(),TODAY()-INT(INDEX(App_NextDate,$N14)),""),"")) | I14: =IF($N14="","",IF(ISNUMBER(INDEX(App_DateApplied,$N14)),INDEX(App_DateApplied,$N14),"")) | J14: =IF($N14="","",IF(ISNUMBER(INDEX(App_DateApplied,$N14)),TODAY()-INT(INDEX(App_DateApplied,$N14)),"")) | K14: =IF($N14="","",INDEX(App_Priority,$N14)&"") | L14: =IF($N14="","",INDEX(App_Contact,$N14)&"") | M14: =IF($N14="","",IF(INDEX(App_URL,$N14)="","",HYPERLINK(INDEX(App_URL,$N14),"Open ↗"))) | N14: =IFERROR(MATCH(SMALL(App_ActionKey,5),App_ActionKey,0),"")
B15: =IF($N15="","",INDEX(App_Flag,$N15)&"") | C15: =IF($N15="","",INDEX(App_Company,$N15)&"") | D15: =IF($N15="","",INDEX(App_JobTitle,$N15)&"") | E15: =IF($N15="","",INDEX(App_Status,$N15)&"") | F15: =IF($N15="","",INDEX(App_NextAction,$N15)&"") | G15: =IF($N15="","",IF(ISNUMBER(INDEX(App_NextDate,$N15)),INDEX(App_NextDate,$N15),"")) | H15: =IF($N15="","",IF(ISNUMBER(INDEX(App_NextDate,$N15)),IF(INT(INDEX(App_NextDate,$N15))<TODAY(),TODAY()-INT(INDEX(App_NextDate,$N15)),""),"")) | I15: =IF($N15="","",IF(ISNUMBER(INDEX(App_DateApplied,$N15)),INDEX(App_DateApplied,$N15),"")) | J15: =IF($N15="","",IF(ISNUMBER(INDEX(App_DateApplied,$N15)),TODAY()-INT(INDEX(App_DateApplied,$N15)),"")) | K15: =IF($N15="","",INDEX(App_Priority,$N15)&"") | L15: =IF($N15="","",INDEX(App_Contact,$N15)&"") | M15: =IF($N15="","",IF(INDEX(App_URL,$N15)="","",HYPERLINK(INDEX(App_URL,$N15),"Open ↗"))) | N15: =IFERROR(MATCH(SMALL(App_ActionKey,6),App_ActionKey,0),"")
B16: =IF($N16="","",INDEX(App_Flag,$N16)&"") | C16: =IF($N16="","",INDEX(App_Company,$N16)&"") | D16: =IF($N16="","",INDEX(App_JobTitle,$N16)&"") | E16: =IF($N16="","",INDEX(App_Status,$N16)&"") | F16: =IF($N16="","",INDEX(App_NextAction,$N16)&"") | G16: =IF($N16="","",IF(ISNUMBER(INDEX(App_NextDate,$N16)),INDEX(App_NextDate,$N16),"")) | H16: =IF($N16="","",IF(ISNUMBER(INDEX(App_NextDate,$N16)),IF(INT(INDEX(App_NextDate,$N16))<TODAY(),TODAY()-INT(INDEX(App_NextDate,$N16)),""),"")) | I16: =IF($N16="","",IF(ISNUMBER(INDEX(App_DateApplied,$N16)),INDEX(App_DateApplied,$N16),"")) | J16: =IF($N16="","",IF(ISNUMBER(INDEX(App_DateApplied,$N16)),TODAY()-INT(INDEX(App_DateApplied,$N16)),"")) | K16: =IF($N16="","",INDEX(App_Priority,$N16)&"") | L16: =IF($N16="","",INDEX(App_Contact,$N16)&"") | M16: =IF($N16="","",IF(INDEX(App_URL,$N16)="","",HYPERLINK(INDEX(App_URL,$N16),"Open ↗"))) | N16: =IFERROR(MATCH(SMALL(App_ActionKey,7),App_ActionKey,0),"")
B17: =IF($N17="","",INDEX(App_Flag,$N17)&"") | C17: =IF($N17="","",INDEX(App_Company,$N17)&"") | D17: =IF($N17="","",INDEX(App_JobTitle,$N17)&"") | E17: =IF($N17="","",INDEX(App_Status,$N17)&"") | F17: =IF($N17="","",INDEX(App_NextAction,$N17)&"") | G17: =IF($N17="","",IF(ISNUMBER(INDEX(App_NextDate,$N17)),INDEX(App_NextDate,$N17),"")) | H17: =IF($N17="","",IF(ISNUMBER(INDEX(App_NextDate,$N17)),IF(INT(INDEX(App_NextDate,$N17))<TODAY(),TODAY()-INT(INDEX(App_NextDate,$N17)),""),"")) | I17: =IF($N17="","",IF(ISNUMBER(INDEX(App_DateApplied,$N17)),INDEX(App_DateApplied,$N17),"")) | J17: =IF($N17="","",IF(ISNUMBER(INDEX(App_DateApplied,$N17)),TODAY()-INT(INDEX(App_DateApplied,$N17)),"")) | K17: =IF($N17="","",INDEX(App_Priority,$N17)&"") | L17: =IF($N17="","",INDEX(App_Contact,$N17)&"") | M17: =IF($N17="","",IF(INDEX(App_URL,$N17)="","",HYPERLINK(INDEX(App_URL,$N17),"Open ↗"))) | N17: =IFERROR(MATCH(SMALL(App_ActionKey,8),App_ActionKey,0),"")
B18: =IF($N18="","",INDEX(App_Flag,$N18)&"") | C18: =IF($N18="","",INDEX(App_Company,$N18)&"") | D18: =IF($N18="","",INDEX(App_JobTitle,$N18)&"") | E18: =IF($N18="","",INDEX(App_Status,$N18)&"") | F18: =IF($N18="","",INDEX(App_NextAction,$N18)&"") | G18: =IF($N18="","",IF(ISNUMBER(INDEX(App_NextDate,$N18)),INDEX(App_NextDate,$N18),"")) | H18: =IF($N18="","",IF(ISNUMBER(INDEX(App_NextDate,$N18)),IF(INT(INDEX(App_NextDate,$N18))<TODAY(),TODAY()-INT(INDEX(App_NextDate,$N18)),""),"")) | I18: =IF($N18="","",IF(ISNUMBER(INDEX(App_DateApplied,$N18)),INDEX(App_DateApplied,$N18),"")) | J18: =IF($N18="","",IF(ISNUMBER(INDEX(App_DateApplied,$N18)),TODAY()-INT(INDEX(App_DateApplied,$N18)),"")) | K18: =IF($N18="","",INDEX(App_Priority,$N18)&"") | L18: =IF($N18="","",INDEX(App_Contact,$N18)&"") | M18: =IF($N18="","",IF(INDEX(App_URL,$N18)="","",HYPERLINK(INDEX(App_URL,$N18),"Open ↗"))) | N18: =IFERROR(MATCH(SMALL(App_ActionKey,9),App_ActionKey,0),"")
B19: =IF($N19="","",INDEX(App_Flag,$N19)&"") | C19: =IF($N19="","",INDEX(App_Company,$N19)&"") | D19: =IF($N19="","",INDEX(App_JobTitle,$N19)&"") | E19: =IF($N19="","",INDEX(App_Status,$N19)&"") | F19: =IF($N19="","",INDEX(App_NextAction,$N19)&"") | G19: =IF($N19="","",IF(ISNUMBER(INDEX(App_NextDate,$N19)),INDEX(App_NextDate,$N19),"")) | H19: =IF($N19="","",IF(ISNUMBER(INDEX(App_NextDate,$N19)),IF(INT(INDEX(App_NextDate,$N19))<TODAY(),TODAY()-INT(INDEX(App_NextDate,$N19)),""),"")) | I19: =IF($N19="","",IF(ISNUMBER(INDEX(App_DateApplied,$N19)),INDEX(App_DateApplied,$N19),"")) | J19: =IF($N19="","",IF(ISNUMBER(INDEX(App_DateApplied,$N19)),TODAY()-INT(INDEX(App_DateApplied,$N19)),"")) | K19: =IF($N19="","",INDEX(App_Priority,$N19)&"") | L19: =IF($N19="","",INDEX(App_Contact,$N19)&"") | M19: =IF($N19="","",IF(INDEX(App_URL,$N19)="","",HYPERLINK(INDEX(App_URL,$N19),"Open ↗"))) | N19: =IFERROR(MATCH(SMALL(App_ActionKey,10),App_ActionKey,0),"")
B20: =IF($N20="","",INDEX(App_Flag,$N20)&"") | C20: =IF($N20="","",INDEX(App_Company,$N20)&"") | D20: =IF($N20="","",INDEX(App_JobTitle,$N20)&"") | E20: =IF($N20="","",INDEX(App_Status,$N20)&"") | F20: =IF($N20="","",INDEX(App_NextAction,$N20)&"") | G20: =IF($N20="","",IF(ISNUMBER(INDEX(App_NextDate,$N20)),INDEX(App_NextDate,$N20),"")) | H20: =IF($N20="","",IF(ISNUMBER(INDEX(App_NextDate,$N20)),IF(INT(INDEX(App_NextDate,$N20))<TODAY(),TODAY()-INT(INDEX(App_NextDate,$N20)),""),"")) | I20: =IF($N20="","",IF(ISNUMBER(INDEX(App_DateApplied,$N20)),INDEX(App_DateApplied,$N20),"")) | J20: =IF($N20="","",IF(ISNUMBER(INDEX(App_DateApplied,$N20)),TODAY()-INT(INDEX(App_DateApplied,$N20)),"")) | K20: =IF($N20="","",INDEX(App_Priority,$N20)&"") | L20: =IF($N20="","",INDEX(App_Contact,$N20)&"") | M20: =IF($N20="","",IF(INDEX(App_URL,$N20)="","",HYPERLINK(INDEX(App_URL,$N20),"Open ↗"))) | N20: =IFERROR(MATCH(SMALL(App_ActionKey,11),App_ActionKey,0),"")
B21: =IF($N21="","",INDEX(App_Flag,$N21)&"") | C21: =IF($N21="","",INDEX(App_Company,$N21)&"") | D21: =IF($N21="","",INDEX(App_JobTitle,$N21)&"") | E21: =IF($N21="","",INDEX(App_Status,$N21)&"") | F21: =IF($N21="","",INDEX(App_NextAction,$N21)&"") | G21: =IF($N21="","",IF(ISNUMBER(INDEX(App_NextDate,$N21)),INDEX(App_NextDate,$N21),"")) | H21: =IF($N21="","",IF(ISNUMBER(INDEX(App_NextDate,$N21)),IF(INT(INDEX(App_NextDate,$N21))<TODAY(),TODAY()-INT(INDEX(App_NextDate,$N21)),""),"")) | I21: =IF($N21="","",IF(ISNUMBER(INDEX(App_DateApplied,$N21)),INDEX(App_DateApplied,$N21),"")) | J21: =IF($N21="","",IF(ISNUMBER(INDEX(App_DateApplied,$N21)),TODAY()-INT(INDEX(App_DateApplied,$N21)),"")) | K21: =IF($N21="","",INDEX(App_Priority,$N21)&"") | L21: =IF($N21="","",INDEX(App_Contact,$N21)&"") | M21: =IF($N21="","",IF(INDEX(App_URL,$N21)="","",HYPERLINK(INDEX(App_URL,$N21),"Open ↗"))) | N21: =IFERROR(MATCH(SMALL(App_ActionKey,12),App_ActionKey,0),"")
B22: =IF($N22="","",INDEX(App_Flag,$N22)&"") | C22: =IF($N22="","",INDEX(App_Company,$N22)&"") | D22: =IF($N22="","",INDEX(App_JobTitle,$N22)&"") | E22: =IF($N22="","",INDEX(App_Status,$N22)&"") | F22: =IF($N22="","",INDEX(App_NextAction,$N22)&"") | G22: =IF($N22="","",IF(ISNUMBER(INDEX(App_NextDate,$N22)),INDEX(App_NextDate,$N22),"")) | H22: =IF($N22="","",IF(ISNUMBER(INDEX(App_NextDate,$N22)),IF(INT(INDEX(App_NextDate,$N22))<TODAY(),TODAY()-INT(INDEX(App_NextDate,$N22)),""),"")) | I22: =IF($N22="","",IF(ISNUMBER(INDEX(App_DateApplied,$N22)),INDEX(App_DateApplied,$N22),"")) | J22: =IF($N22="","",IF(ISNUMBER(INDEX(App_DateApplied,$N22)),TODAY()-INT(INDEX(App_DateApplied,$N22)),"")) | K22: =IF($N22="","",INDEX(App_Priority,$N22)&"") | L22: =IF($N22="","",INDEX(App_Contact,$N22)&"") | M22: =IF($N22="","",IF(INDEX(App_URL,$N22)="","",HYPERLINK(INDEX(App_URL,$N22),"Open ↗"))) | N22: =IFERROR(MATCH(SMALL(App_ActionKey,13),App_ActionKey,0),"")
B23: =IF($N23="","",INDEX(App_Flag,$N23)&"") | C23: =IF($N23="","",INDEX(App_Company,$N23)&"") | D23: =IF($N23="","",INDEX(App_JobTitle,$N23)&"") | E23: =IF($N23="","",INDEX(App_Status,$N23)&"") | F23: =IF($N23="","",INDEX(App_NextAction,$N23)&"") | G23: =IF($N23="","",IF(ISNUMBER(INDEX(App_NextDate,$N23)),INDEX(App_NextDate,$N23),"")) | H23: =IF($N23="","",IF(ISNUMBER(INDEX(App_NextDate,$N23)),IF(INT(INDEX(App_NextDate,$N23))<TODAY(),TODAY()-INT(INDEX(App_NextDate,$N23)),""),"")) | I23: =IF($N23="","",IF(ISNUMBER(INDEX(App_DateApplied,$N23)),INDEX(App_DateApplied,$N23),"")) | J23: =IF($N23="","",IF(ISNUMBER(INDEX(App_DateApplied,$N23)),TODAY()-INT(INDEX(App_DateApplied,$N23)),"")) | K23: =IF($N23="","",INDEX(App_Priority,$N23)&"") | L23: =IF($N23="","",INDEX(App_Contact,$N23)&"") | M23: =IF($N23="","",IF(INDEX(App_URL,$N23)="","",HYPERLINK(INDEX(App_URL,$N23),"Open ↗"))) | N23: =IFERROR(MATCH(SMALL(App_ActionKey,14),App_ActionKey,0),"")
B24: =IF($N24="","",INDEX(App_Flag,$N24)&"") | C24: =IF($N24="","",INDEX(App_Company,$N24)&"") | D24: =IF($N24="","",INDEX(App_JobTitle,$N24)&"") | E24: =IF($N24="","",INDEX(App_Status,$N24)&"") | F24: =IF($N24="","",INDEX(App_NextAction,$N24)&"") | G24: =IF($N24="","",IF(ISNUMBER(INDEX(App_NextDate,$N24)),INDEX(App_NextDate,$N24),"")) | H24: =IF($N24="","",IF(ISNUMBER(INDEX(App_NextDate,$N24)),IF(INT(INDEX(App_NextDate,$N24))<TODAY(),TODAY()-INT(INDEX(App_NextDate,$N24)),""),"")) | I24: =IF($N24="","",IF(ISNUMBER(INDEX(App_DateApplied,$N24)),INDEX(App_DateApplied,$N24),"")) | J24: =IF($N24="","",IF(ISNUMBER(INDEX(App_DateApplied,$N24)),TODAY()-INT(INDEX(App_DateApplied,$N24)),"")) | K24: =IF($N24="","",INDEX(App_Priority,$N24)&"") | L24: =IF($N24="","",INDEX(App_Contact,$N24)&"") | M24: =IF($N24="","",IF(INDEX(App_URL,$N24)="","",HYPERLINK(INDEX(App_URL,$N24),"Open ↗"))) | N24: =IFERROR(MATCH(SMALL(App_ActionKey,15),App_ActionKey,0),"")
B25: =IF($N25="","",INDEX(App_Flag,$N25)&"") | C25: =IF($N25="","",INDEX(App_Company,$N25)&"") | D25: =IF($N25="","",INDEX(App_JobTitle,$N25)&"") | E25: =IF($N25="","",INDEX(App_Status,$N25)&"") | F25: =IF($N25="","",INDEX(App_NextAction,$N25)&"") | G25: =IF($N25="","",IF(ISNUMBER(INDEX(App_NextDate,$N25)),INDEX(App_NextDate,$N25),"")) | H25: =IF($N25="","",IF(ISNUMBER(INDEX(App_NextDate,$N25)),IF(INT(INDEX(App_NextDate,$N25))<TODAY(),TODAY()-INT(INDEX(App_NextDate,$N25)),""),"")) | I25: =IF($N25="","",IF(ISNUMBER(INDEX(App_DateApplied,$N25)),INDEX(App_DateApplied,$N25),"")) | J25: =IF($N25="","",IF(ISNUMBER(INDEX(App_DateApplied,$N25)),TODAY()-INT(INDEX(App_DateApplied,$N25)),"")) | K25: =IF($N25="","",INDEX(App_Priority,$N25)&"") | L25: =IF($N25="","",INDEX(App_Contact,$N25)&"") | M25: =IF($N25="","",IF(INDEX(App_URL,$N25)="","",HYPERLINK(INDEX(App_URL,$N25),"Open ↗"))) | N25: =IFERROR(MATCH(SMALL(App_ActionKey,16),App_ActionKey,0),"")
B26: =IF($N26="","",INDEX(App_Flag,$N26)&"") | C26: =IF($N26="","",INDEX(App_Company,$N26)&"") | D26: =IF($N26="","",INDEX(App_JobTitle,$N26)&"") | E26: =IF($N26="","",INDEX(App_Status,$N26)&"") | F26: =IF($N26="","",INDEX(App_NextAction,$N26)&"") | G26: =IF($N26="","",IF(ISNUMBER(INDEX(App_NextDate,$N26)),INDEX(App_NextDate,$N26),"")) | H26: =IF($N26="","",IF(ISNUMBER(INDEX(App_NextDate,$N26)),IF(INT(INDEX(App_NextDate,$N26))<TODAY(),TODAY()-INT(INDEX(App_NextDate,$N26)),""),"")) | I26: =IF($N26="","",IF(ISNUMBER(INDEX(App_DateApplied,$N26)),INDEX(App_DateApplied,$N26),"")) | J26: =IF($N26="","",IF(ISNUMBER(INDEX(App_DateApplied,$N26)),TODAY()-INT(INDEX(App_DateApplied,$N26)),"")) | K26: =IF($N26="","",INDEX(App_Priority,$N26)&"") | L26: =IF($N26="","",INDEX(App_Contact,$N26)&"") | M26: =IF($N26="","",IF(INDEX(App_URL,$N26)="","",HYPERLINK(INDEX(App_URL,$N26),"Open ↗"))) | N26: =IFERROR(MATCH(SMALL(App_ActionKey,17),App_ActionKey,0),"")
B27: =IF($N27="","",INDEX(App_Flag,$N27)&"") | C27: =IF($N27="","",INDEX(App_Company,$N27)&"") | D27: =IF($N27="","",INDEX(App_JobTitle,$N27)&"") | E27: =IF($N27="","",INDEX(App_Status,$N27)&"") | F27: =IF($N27="","",INDEX(App_NextAction,$N27)&"") | G27: =IF($N27="","",IF(ISNUMBER(INDEX(App_NextDate,$N27)),INDEX(App_NextDate,$N27),"")) | H27: =IF($N27="","",IF(ISNUMBER(INDEX(App_NextDate,$N27)),IF(INT(INDEX(App_NextDate,$N27))<TODAY(),TODAY()-INT(INDEX(App_NextDate,$N27)),""),"")) | I27: =IF($N27="","",IF(ISNUMBER(INDEX(App_DateApplied,$N27)),INDEX(App_DateApplied,$N27),"")) | J27: =IF($N27="","",IF(ISNUMBER(INDEX(App_DateApplied,$N27)),TODAY()-INT(INDEX(App_DateApplied,$N27)),"")) | K27: =IF($N27="","",INDEX(App_Priority,$N27)&"") | L27: =IF($N27="","",INDEX(App_Contact,$N27)&"") | M27: =IF($N27="","",IF(INDEX(App_URL,$N27)="","",HYPERLINK(INDEX(App_URL,$N27),"Open ↗"))) | N27: =IFERROR(MATCH(SMALL(App_ActionKey,18),App_ActionKey,0),"")
B28: =IF($N28="","",INDEX(App_Flag,$N28)&"") | C28: =IF($N28="","",INDEX(App_Company,$N28)&"") | D28: =IF($N28="","",INDEX(App_JobTitle,$N28)&"") | E28: =IF($N28="","",INDEX(App_Status,$N28)&"") | F28: =IF($N28="","",INDEX(App_NextAction,$N28)&"") | G28: =IF($N28="","",IF(ISNUMBER(INDEX(App_NextDate,$N28)),INDEX(App_NextDate,$N28),"")) | H28: =IF($N28="","",IF(ISNUMBER(INDEX(App_NextDate,$N28)),IF(INT(INDEX(App_NextDate,$N28))<TODAY(),TODAY()-INT(INDEX(App_NextDate,$N28)),""),"")) | I28: =IF($N28="","",IF(ISNUMBER(INDEX(App_DateApplied,$N28)),INDEX(App_DateApplied,$N28),"")) | J28: =IF($N28="","",IF(ISNUMBER(INDEX(App_DateApplied,$N28)),TODAY()-INT(INDEX(App_DateApplied,$N28)),"")) | K28: =IF($N28="","",INDEX(App_Priority,$N28)&"") | L28: =IF($N28="","",INDEX(App_Contact,$N28)&"") | M28: =IF($N28="","",IF(INDEX(App_URL,$N28)="","",HYPERLINK(INDEX(App_URL,$N28),"Open ↗"))) | N28: =IFERROR(MATCH(SMALL(App_ActionKey,19),App_ActionKey,0),"")
B29: =IF($N29="","",INDEX(App_Flag,$N29)&"") | C29: =IF($N29="","",INDEX(App_Company,$N29)&"") | D29: =IF($N29="","",INDEX(App_JobTitle,$N29)&"") | E29: =IF($N29="","",INDEX(App_Status,$N29)&"") | F29: =IF($N29="","",INDEX(App_NextAction,$N29)&"") | G29: =IF($N29="","",IF(ISNUMBER(INDEX(App_NextDate,$N29)),INDEX(App_NextDate,$N29),"")) | H29: =IF($N29="","",IF(ISNUMBER(INDEX(App_NextDate,$N29)),IF(INT(INDEX(App_NextDate,$N29))<TODAY(),TODAY()-INT(INDEX(App_NextDate,$N29)),""),"")) | I29: =IF($N29="","",IF(ISNUMBER(INDEX(App_DateApplied,$N29)),INDEX(App_DateApplied,$N29),"")) | J29: =IF($N29="","",IF(ISNUMBER(INDEX(App_DateApplied,$N29)),TODAY()-INT(INDEX(App_DateApplied,$N29)),"")) | K29: =IF($N29="","",INDEX(App_Priority,$N29)&"") | L29: =IF($N29="","",INDEX(App_Contact,$N29)&"") | M29: =IF($N29="","",IF(INDEX(App_URL,$N29)="","",HYPERLINK(INDEX(App_URL,$N29),"Open ↗"))) | N29: =IFERROR(MATCH(SMALL(App_ActionKey,20),App_ActionKey,0),"")
B30: =IF($N30="","",INDEX(App_Flag,$N30)&"") | C30: =IF($N30="","",INDEX(App_Company,$N30)&"") | D30: =IF($N30="","",INDEX(App_JobTitle,$N30)&"") | E30: =IF($N30="","",INDEX(App_Status,$N30)&"") | F30: =IF($N30="","",INDEX(App_NextAction,$N30)&"") | G30: =IF($N30="","",IF(ISNUMBER(INDEX(App_NextDate,$N30)),INDEX(App_NextDate,$N30),"")) | H30: =IF($N30="","",IF(ISNUMBER(INDEX(App_NextDate,$N30)),IF(INT(INDEX(App_NextDate,$N30))<TODAY(),TODAY()-INT(INDEX(App_NextDate,$N30)),""),"")) | I30: =IF($N30="","",IF(ISNUMBER(INDEX(App_DateApplied,$N30)),INDEX(App_DateApplied,$N30),"")) | J30: =IF($N30="","",IF(ISNUMBER(INDEX(App_DateApplied,$N30)),TODAY()-INT(INDEX(App_DateApplied,$N30)),"")) | K30: =IF($N30="","",INDEX(App_Priority,$N30)&"") | L30: =IF($N30="","",INDEX(App_Contact,$N30)&"") | M30: =IF($N30="","",IF(INDEX(App_URL,$N30)="","",HYPERLINK(INDEX(App_URL,$N30),"Open ↗"))) | N30: =IFERROR(MATCH(SMALL(App_ActionKey,21),App_ActionKey,0),"")
B31: =IF($N31="","",INDEX(App_Flag,$N31)&"") | C31: =IF($N31="","",INDEX(App_Company,$N31)&"") | D31: =IF($N31="","",INDEX(App_JobTitle,$N31)&"") | E31: =IF($N31="","",INDEX(App_Status,$N31)&"") | F31: =IF($N31="","",INDEX(App_NextAction,$N31)&"") | G31: =IF($N31="","",IF(ISNUMBER(INDEX(App_NextDate,$N31)),INDEX(App_NextDate,$N31),"")) | H31: =IF($N31="","",IF(ISNUMBER(INDEX(App_NextDate,$N31)),IF(INT(INDEX(App_NextDate,$N31))<TODAY(),TODAY()-INT(INDEX(App_NextDate,$N31)),""),"")) | I31: =IF($N31="","",IF(ISNUMBER(INDEX(App_DateApplied,$N31)),INDEX(App_DateApplied,$N31),"")) | J31: =IF($N31="","",IF(ISNUMBER(INDEX(App_DateApplied,$N31)),TODAY()-INT(INDEX(App_DateApplied,$N31)),"")) | K31: =IF($N31="","",INDEX(App_Priority,$N31)&"") | L31: =IF($N31="","",INDEX(App_Contact,$N31)&"") | M31: =IF($N31="","",IF(INDEX(App_URL,$N31)="","",HYPERLINK(INDEX(App_URL,$N31),"Open ↗"))) | N31: =IFERROR(MATCH(SMALL(App_ActionKey,22),App_ActionKey,0),"")
B32: =IF($N32="","",INDEX(App_Flag,$N32)&"") | C32: =IF($N32="","",INDEX(App_Company,$N32)&"") | D32: =IF($N32="","",INDEX(App_JobTitle,$N32)&"") | E32: =IF($N32="","",INDEX(App_Status,$N32)&"") | F32: =IF($N32="","",INDEX(App_NextAction,$N32)&"") | G32: =IF($N32="","",IF(ISNUMBER(INDEX(App_NextDate,$N32)),INDEX(App_NextDate,$N32),"")) | H32: =IF($N32="","",IF(ISNUMBER(INDEX(App_NextDate,$N32)),IF(INT(INDEX(App_NextDate,$N32))<TODAY(),TODAY()-INT(INDEX(App_NextDate,$N32)),""),"")) | I32: =IF($N32="","",IF(ISNUMBER(INDEX(App_DateApplied,$N32)),INDEX(App_DateApplied,$N32),"")) | J32: =IF($N32="","",IF(ISNUMBER(INDEX(App_DateApplied,$N32)),TODAY()-INT(INDEX(App_DateApplied,$N32)),"")) | K32: =IF($N32="","",INDEX(App_Priority,$N32)&"") | L32: =IF($N32="","",INDEX(App_Contact,$N32)&"") | M32: =IF($N32="","",IF(INDEX(App_URL,$N32)="","",HYPERLINK(INDEX(App_URL,$N32),"Open ↗"))) | N32: =IFERROR(MATCH(SMALL(App_ActionKey,23),App_ActionKey,0),"")
B33: =IF($N33="","",INDEX(App_Flag,$N33)&"") | C33: =IF($N33="","",INDEX(App_Company,$N33)&"") | D33: =IF($N33="","",INDEX(App_JobTitle,$N33)&"") | E33: =IF($N33="","",INDEX(App_Status,$N33)&"") | F33: =IF($N33="","",INDEX(App_NextAction,$N33)&"") | G33: =IF($N33="","",IF(ISNUMBER(INDEX(App_NextDate,$N33)),INDEX(App_NextDate,$N33),"")) | H33: =IF($N33="","",IF(ISNUMBER(INDEX(App_NextDate,$N33)),IF(INT(INDEX(App_NextDate,$N33))<TODAY(),TODAY()-INT(INDEX(App_NextDate,$N33)),""),"")) | I33: =IF($N33="","",IF(ISNUMBER(INDEX(App_DateApplied,$N33)),INDEX(App_DateApplied,$N33),"")) | J33: =IF($N33="","",IF(ISNUMBER(INDEX(App_DateApplied,$N33)),TODAY()-INT(INDEX(App_DateApplied,$N33)),"")) | K33: =IF($N33="","",INDEX(App_Priority,$N33)&"") | L33: =IF($N33="","",INDEX(App_Contact,$N33)&"") | M33: =IF($N33="","",IF(INDEX(App_URL,$N33)="","",HYPERLINK(INDEX(App_URL,$N33),"Open ↗"))) | N33: =IFERROR(MATCH(SMALL(App_ActionKey,24),App_ActionKey,0),"")
B34: =IF($N34="","",INDEX(App_Flag,$N34)&"") | C34: =IF($N34="","",INDEX(App_Company,$N34)&"") | D34: =IF($N34="","",INDEX(App_JobTitle,$N34)&"") | E34: =IF($N34="","",INDEX(App_Status,$N34)&"") | F34: =IF($N34="","",INDEX(App_NextAction,$N34)&"") | G34: =IF($N34="","",IF(ISNUMBER(INDEX(App_NextDate,$N34)),INDEX(App_NextDate,$N34),"")) | H34: =IF($N34="","",IF(ISNUMBER(INDEX(App_NextDate,$N34)),IF(INT(INDEX(App_NextDate,$N34))<TODAY(),TODAY()-INT(INDEX(App_NextDate,$N34)),""),"")) | I34: =IF($N34="","",IF(ISNUMBER(INDEX(App_DateApplied,$N34)),INDEX(App_DateApplied,$N34),"")) | J34: =IF($N34="","",IF(ISNUMBER(INDEX(App_DateApplied,$N34)),TODAY()-INT(INDEX(App_DateApplied,$N34)),"")) | K34: =IF($N34="","",INDEX(App_Priority,$N34)&"") | L34: =IF($N34="","",INDEX(App_Contact,$N34)&"") | M34: =IF($N34="","",IF(INDEX(App_URL,$N34)="","",HYPERLINK(INDEX(App_URL,$N34),"Open ↗"))) | N34: =IFERROR(MATCH(SMALL(App_ActionKey,25),App_ActionKey,0),"")
B35: =IF(COUNT(App_ActionKey)>25,"+ "&(COUNT(App_ActionKey)-25)&" more — filter the Action Flag column on Applications","")
B37: ="UPCOMING INTERVIEWS — NEXT "&Set_InterviewWindow&" DAYS"
B38: Interview Date | C38: Company | D38: Job Title | E38: Stage | F38: Interview Type | G38: Days Until | H38: Preparation | I38: Interviewer | L38: Next Step
B39: =IF($N39="","",IF(ISNUMBER(INDEX(Int_Date,$N39)),INDEX(Int_Date,$N39),"")) | C39: =IF($N39="","",INDEX(Int_Company,$N39)&"") | D39: =IF($N39="","",INDEX(Int_JobTitle,$N39)&"") | E39: =IF($N39="","",INDEX(Int_Stage,$N39)&"") | F39: =IF($N39="","",INDEX(Int_Type,$N39)&"") | G39: =IF($N39="","",IF(ISNUMBER(INDEX(Int_Date,$N39)),INT(INDEX(Int_Date,$N39))-TODAY(),"")) | H39: =IF($N39="","",INDEX(Int_Prep,$N39)&"") | I39: =IF($N39="","",INDEX(Int_Interviewer,$N39)&"") | L39: =IF($N39="","",INDEX(Int_NextStep,$N39)&"") | N39: =IFERROR(MATCH(SMALL(Int_Key,1),Int_Key,0),"")
B40: =IF($N40="","",IF(ISNUMBER(INDEX(Int_Date,$N40)),INDEX(Int_Date,$N40),"")) | C40: =IF($N40="","",INDEX(Int_Company,$N40)&"") | D40: =IF($N40="","",INDEX(Int_JobTitle,$N40)&"") | E40: =IF($N40="","",INDEX(Int_Stage,$N40)&"") | F40: =IF($N40="","",INDEX(Int_Type,$N40)&"") | G40: =IF($N40="","",IF(ISNUMBER(INDEX(Int_Date,$N40)),INT(INDEX(Int_Date,$N40))-TODAY(),"")) | H40: =IF($N40="","",INDEX(Int_Prep,$N40)&"") | I40: =IF($N40="","",INDEX(Int_Interviewer,$N40)&"") | L40: =IF($N40="","",INDEX(Int_NextStep,$N40)&"") | N40: =IFERROR(MATCH(SMALL(Int_Key,2),Int_Key,0),"")
B41: =IF($N41="","",IF(ISNUMBER(INDEX(Int_Date,$N41)),INDEX(Int_Date,$N41),"")) | C41: =IF($N41="","",INDEX(Int_Company,$N41)&"") | D41: =IF($N41="","",INDEX(Int_JobTitle,$N41)&"") | E41: =IF($N41="","",INDEX(Int_Stage,$N41)&"") | F41: =IF($N41="","",INDEX(Int_Type,$N41)&"") | G41: =IF($N41="","",IF(ISNUMBER(INDEX(Int_Date,$N41)),INT(INDEX(Int_Date,$N41))-TODAY(),"")) | H41: =IF($N41="","",INDEX(Int_Prep,$N41)&"") | I41: =IF($N41="","",INDEX(Int_Interviewer,$N41)&"") | L41: =IF($N41="","",INDEX(Int_NextStep,$N41)&"") | N41: =IFERROR(MATCH(SMALL(Int_Key,3),Int_Key,0),"")
B42: =IF($N42="","",IF(ISNUMBER(INDEX(Int_Date,$N42)),INDEX(Int_Date,$N42),"")) | C42: =IF($N42="","",INDEX(Int_Company,$N42)&"") | D42: =IF($N42="","",INDEX(Int_JobTitle,$N42)&"") | E42: =IF($N42="","",INDEX(Int_Stage,$N42)&"") | F42: =IF($N42="","",INDEX(Int_Type,$N42)&"") | G42: =IF($N42="","",IF(ISNUMBER(INDEX(Int_Date,$N42)),INT(INDEX(Int_Date,$N42))-TODAY(),"")) | H42: =IF($N42="","",INDEX(Int_Prep,$N42)&"") | I42: =IF($N42="","",INDEX(Int_Interviewer,$N42)&"") | L42: =IF($N42="","",INDEX(Int_NextStep,$N42)&"") | N42: =IFERROR(MATCH(SMALL(Int_Key,4),Int_Key,0),"")
B43: =IF($N43="","",IF(ISNUMBER(INDEX(Int_Date,$N43)),INDEX(Int_Date,$N43),"")) | C43: =IF($N43="","",INDEX(Int_Company,$N43)&"") | D43: =IF($N43="","",INDEX(Int_JobTitle,$N43)&"") | E43: =IF($N43="","",INDEX(Int_Stage,$N43)&"") | F43: =IF($N43="","",INDEX(Int_Type,$N43)&"") | G43: =IF($N43="","",IF(ISNUMBER(INDEX(Int_Date,$N43)),INT(INDEX(Int_Date,$N43))-TODAY(),"")) | H43: =IF($N43="","",INDEX(Int_Prep,$N43)&"") | I43: =IF($N43="","",INDEX(Int_Interviewer,$N43)&"") | L43: =IF($N43="","",INDEX(Int_NextStep,$N43)&"") | N43: =IFERROR(MATCH(SMALL(Int_Key,5),Int_Key,0),"")
...

Sheet Applications
A1: Applications | AG1: Follow-up days | AH1: Due-soon days
A2: One row per job. Status drives the pipeline · Next Action Date drives Follow-Ups · Match % is your own assessment. | AG2: =Set_FollowUpDays | AH2: =Set_DueSoonDays
A3: Next ID | B3: =MAX(App_ID)+1 | D3: White columns = your input · Grey columns = auto-calculated (don't type over them) · Dates as dd.mm.yyyy (Ctrl+; = today) | Z3: EXTRA TRACKING FIELDS ▸ your input | AC3: AUTO-CALCULATED ▸ don't edit
A4: Application ID | B4: Date Added | C4: Date Applied | D4: Company | E4: Job Title | F4: Job Type | G4: Location | H4: Remote / Hybrid / On-site | I4: Job URL | J4: Source | K4: Priority | L4: Match % | M4: Status | N4: Next Action | O4: Next Action Date | P4: Recruiter / Hiring Manager | Q4: Recruiter LinkedIn | R4: CV Version | S4: Cover Letter | T4: Referral | U4: Salary / Salary Range | V4: Key Technologies / Skills | W4: Why Me? | X4: Notes | Y4: Last Updated | Z4: Role Category | AA4: First Response Date | AB4: Stage When Closed | AC4: Action Flag | AD4: Match Category | AE4: Furthest Stage | AF4: Days to Response | AG4: Stage # (helper) | AH4: Action Sort Key (helper) | AI4: Active Sort Key (helper)
AC5: =IF(OR($D5="",$M5="Rejected",$M5="Withdrawn",$M5="Accepted"),"",IF(ISNUMBER($O5),IF(INT($O5)<TODAY(),"FOLLOW UP REQUIRED",IF(INT($O5)=TODAY(),"ACTION DUE TODAY",IF(INT($O5)-TODAY()<=Set_DueSoonDays,"DUE SOON",""))),IF(AND($M5="Applied",$AA5=""),IF(ISNUMBER($C5),IF(TODAY()-$C5>=Set_FollowUpDays,"NO RESPONSE",""),""),""))) | AD5: =IF(ISNUMBER($L5),IF($L5>=90,"Excellent Match",IF($L5>=75,"Strong Match",IF($L5>=60,"Moderate Match","Low Match"))),"") | AE5: =IF($D5="","",IF(OR($M5="Rejected",$M5="Withdrawn"),IF($AB5<>"",$AB5,IF(OR($M5="Rejected",ISNUMBER($C5)),"Applied","Wishlist")),IF($M5="",IF(ISNUMBER($C5),"Applied","Wishlist"),$M5))) | AF5: =IF(AND(ISNUMBER($C5),ISNUMBER($AA5)),$AA5-$C5,"") | AG5: =IF($AE5="","",IFERROR(MATCH($AE5,{"Wishlist","Applied","Screening","Interview 1","Interview 2","Final","Offer","Accepted"},0)-1,"")) | AH5: =IF($AC5="","",MATCH($AC5,{"FOLLOW UP REQUIRED","ACTION DUE TODAY","NO RESPONSE","DUE SOON"},0)*100000+IF(ISNUMBER($O5),$O5,IF(ISNUMBER($C5),$C5,0))+ROW()/10000) | AI5: =IF(AND(ISNUMBER($AG5),$AG5>=1,$AG5<=6,$M5<>"Rejected",$M5<>"Withdrawn"),(10-$AG5)*100000+IF(ISNUMBER($C5),$C5,0)+ROW()/10000,"")
AC6: =IF(OR($D6="",$M6="Rejected",$M6="Withdrawn",$M6="Accepted"),"",IF(ISNUMBER($O6),IF(INT($O6)<TODAY(),"FOLLOW UP REQUIRED",IF(INT($O6)=TODAY(),"ACTION DUE TODAY",IF(INT($O6)-TODAY()<=Set_DueSoonDays,"DUE SOON",""))),IF(AND($M6="Applied",$AA6=""),IF(ISNUMBER($C6),IF(TODAY()-$C6>=Set_FollowUpDays,"NO RESPONSE",""),""),""))) | AD6: =IF(ISNUMBER($L6),IF($L6>=90,"Excellent Match",IF($L6>=75,"Strong Match",IF($L6>=60,"Moderate Match","Low Match"))),"") | AE6: =IF($D6="","",IF(OR($M6="Rejected",$M6="Withdrawn"),IF($AB6<>"",$AB6,IF(OR($M6="Rejected",ISNUMBER($C6)),"Applied","Wishlist")),IF($M6="",IF(ISNUMBER($C6),"Applied","Wishlist"),$M6))) | AF6: =IF(AND(ISNUMBER($C6),ISNUMBER($AA6)),$AA6-$C6,"") | AG6: =IF($AE6="","",IFERROR(MATCH($AE6,{"Wishlist","Applied","Screening","Interview 1","Interview 2","Final","Offer","Accepted"},0)-1,"")) | AH6: =IF($AC6="","",MATCH($AC6,{"FOLLOW UP REQUIRED","ACTION DUE TODAY","NO RESPONSE","DUE SOON"},0)*100000+IF(ISNUMBER($O6),$O6,IF(ISNUMBER($C6),$C6,0))+ROW()/10000) | AI6: =IF(AND(ISNUMBER($AG6),$AG6>=1,$AG6<=6,$M6<>"Rejected",$M6<>"Withdrawn"),(10-$AG6)*100000+IF(ISNUMBER($C6),$C6,0)+ROW()/10000,"")
AC7: =IF(OR($D7="",$M7="Rejected",$M7="Withdrawn",$M7="Accepted"),"",IF(ISNUMBER($O7),IF(INT($O7)<TODAY(),"FOLLOW UP REQUIRED",IF(INT($O7)=TODAY(),"ACTION DUE TODAY",IF(INT($O7)-TODAY()<=Set_DueSoonDays,"DUE SOON",""))),IF(AND($M7="Applied",$AA7=""),IF(ISNUMBER($C7),IF(TODAY()-$C7>=Set_FollowUpDays,"NO RESPONSE",""),""),""))) | AD7: =IF(ISNUMBER($L7),IF($L7>=90,"Excellent Match",IF($L7>=75,"Strong Match",IF($L7>=60,"Moderate Match","Low Match"))),"") | AE7: =IF($D7="","",IF(OR($M7="Rejected",$M7="Withdrawn"),IF($AB7<>"",$AB7,IF(OR($M7="Rejected",ISNUMBER($C7)),"Applied","Wishlist")),IF($M7="",IF(ISNUMBER($C7),"Applied","Wishlist"),$M7))) | AF7: =IF(AND(ISNUMBER($C7),ISNUMBER($AA7)),$AA7-$C7,"") | AG7: =IF($AE7="","",IFERROR(MATCH($AE7,{"Wishlist","Applied","Screening","Interview 1","Interview 2","Final","Offer","Accepted"},0)-1,"")) | AH7: =IF($AC7="","",MATCH($AC7,{"FOLLOW UP REQUIRED","ACTION DUE TODAY","NO RESPONSE","DUE SOON"},0)*100000+IF(ISNUMBER($O7),$O7,IF(ISNUMBER($C7),$C7,0))+ROW()/10000) | AI7: =IF(AND(ISNUMBER($AG7),$AG7>=1,$AG7<=6,$M7<>"Rejected",$M7<>"Withdrawn"),(10-$AG7)*100000+IF(ISNUMBER($C7),$C7,0)+ROW()/10000,"")
AC8: =IF(OR($D8="",$M8="Rejected",$M8="Withdrawn",$M8="Accepted"),"",IF(ISNUMBER($O8),IF(INT($O8)<TODAY(),"FOLLOW UP REQUIRED",IF(INT($O8)=TODAY(),"ACTION DUE TODAY",IF(INT($O8)-TODAY()<=Set_DueSoonDays,"DUE SOON",""))),IF(AND($M8="Applied",$AA8=""),IF(ISNUMBER($C8),IF(TODAY()-$C8>=Set_FollowUpDays,"NO RESPONSE",""),""),""))) | AD8: =IF(ISNUMBER($L8),IF($L8>=90,"Excellent Match",IF($L8>=75,"Strong Match",IF($L8>=60,"Moderate Match","Low Match"))),"") | AE8: =IF($D8="","",IF(OR($M8="Rejected",$M8="Withdrawn"),IF($AB8<>"",$AB8,IF(OR($M8="Rejected",ISNUMBER($C8)),"Applied","Wishlist")),IF($M8="",IF(ISNUMBER($C8),"Applied","Wishlist"),$M8))) | AF8: =IF(AND(ISNUMBER($C8),ISNUMBER($AA8)),$AA8-$C8,"") | AG8: =IF($AE8="","",IFERROR(MATCH($AE8,{"Wishlist","Applied","Screening","Interview 1","Interview 2","Final","Offer","Accepted"},0)-1,"")) | AH8: =IF($AC8="","",MATCH($AC8,{"FOLLOW UP REQUIRED","ACTION DUE TODAY","NO RESPONSE","DUE SOON"},0)*100000+IF(ISNUMBER($O8),$O8,IF(ISNUMBER($C8),$C8,0))+ROW()/10000) | AI8: =IF(AND(ISNUMBER($AG8),$AG8>=1,$AG8<=6,$M8<>"Rejected",$M8<>"Withdrawn"),(10-$AG8)*100000+IF(ISNUMBER($C8),$C8,0)+ROW()/10000,"")
AC9: =IF(OR($D9="",$M9="Rejected",$M9="Withdrawn",$M9="Accepted"),"",IF(ISNUMBER($O9),IF(INT($O9)<TODAY(),"FOLLOW UP REQUIRED",IF(INT($O9)=TODAY(),"ACTION DUE TODAY",IF(INT($O9)-TODAY()<=Set_DueSoonDays,"DUE SOON",""))),IF(AND($M9="Applied",$AA9=""),IF(ISNUMBER($C9),IF(TODAY()-$C9>=Set_FollowUpDays,"NO RESPONSE",""),""),""))) | AD9: =IF(ISNUMBER($L9),IF($L9>=90,"Excellent Match",IF($L9>=75,"Strong Match",IF($L9>=60,"Moderate Match","Low Match"))),"") | AE9: =IF($D9="","",IF(OR($M9="Rejected",$M9="Withdrawn"),IF($AB9<>"",$AB9,IF(OR($M9="Rejected",ISNUMBER($C9)),"Applied","Wishlist")),IF($M9="",IF(ISNUMBER($C9),"Applied","Wishlist"),$M9))) | AF9: =IF(AND(ISNUMBER($C9),ISNUMBER($AA9)),$AA9-$C9,"") | AG9: =IF($AE9="","",IFERROR(MATCH($AE9,{"Wishlist","Applied","Screening","Interview 1","Interview 2","Final","Offer","Accepted"},0)-1,"")) | AH9: =IF($AC9="","",MATCH($AC9,{"FOLLOW UP REQUIRED","ACTION DUE TODAY","NO RESPONSE","DUE SOON"},0)*100000+IF(ISNUMBER($O9),$O9,IF(ISNUMBER($C9),$C9,0))+ROW()/10000) | AI9: =IF(AND(ISNUMBER($AG9),$AG9>=1,$AG9<=6,$M9<>"Rejected",$M9<>"Withdrawn"),(10-$AG9)*100000+IF(ISNUMBER($C9),$C9,0)+ROW()/10000,"")
AC10: =IF(OR($D10="",$M10="Rejected",$M10="Withdrawn",$M10="Accepted"),"",IF(ISNUMBER($O10),IF(INT($O10)<TODAY(),"FOLLOW UP REQUIRED",IF(INT($O10)=TODAY(),"ACTION DUE TODAY",IF(INT($O10)-TODAY()<=Set_DueSoonDays,"DUE SOON",""))),IF(AND($M10="Applied",$AA10=""),IF(ISNUMBER($C10),IF(TODAY()-$C10>=Set_FollowUpDays,"NO RESPONSE",""),""),""))) | AD10: =IF(ISNUMBER($L10),IF($L10>=90,"Excellent Match",IF($L10>=75,"Strong Match",IF($L10>=60,"Moderate Match","Low Match"))),"") | AE10: =IF($D10="","",IF(OR($M10="Rejected",$M10="Withdrawn"),IF($AB10<>"",$AB10,IF(OR($M10="Rejected",ISNUMBER($C10)),"Applied","Wishlist")),IF($M10="",IF(ISNUMBER($C10),"Applied","Wishlist"),$M10))) | AF10: =IF(AND(ISNUMBER($C10),ISNUMBER($AA10)),$AA10-$C10,"") | AG10: =IF($AE10="","",IFERROR(MATCH($AE10,{"Wishlist","Applied","Screening","Interview 1","Interview 2","Final","Offer","Accepted"},0)-1,"")) | AH10: =IF($AC10="","",MATCH($AC10,{"FOLLOW UP REQUIRED","ACTION DUE TODAY","NO RESPONSE","DUE SOON"},0)*100000+IF(ISNUMBER($O10),$O10,IF(ISNUMBER($C10),$C10,0))+ROW()/10000) | AI10: =IF(AND(ISNUMBER($AG10),$AG10>=1,$AG10<=6,$M10<>"Rejected",$M10<>"Withdrawn"),(10-$AG10)*100000+IF(ISNUMBER($C10),$C10,0)+ROW()/10000,"")
AC11: =IF(OR($D11="",$M11="Rejected",$M11="Withdrawn",$M11="Accepted"),"",IF(ISNUMBER($O11),IF(INT($O11)<TODAY(),"FOLLOW UP REQUIRED",IF(INT($O11)=TODAY(),"ACTION DUE TODAY",IF(INT($O11)-TODAY()<=Set_DueSoonDays,"DUE SOON",""))),IF(AND($M11="Applied",$AA11=""),IF(ISNUMBER($C11),IF(TODAY()-$C11>=Set_FollowUpDays,"NO RESPONSE",""),""),""))) | AD11: =IF(ISNUMBER($L11),IF($L11>=90,"Excellent Match",IF($L11>=75,"Strong Match",IF($L11>=60,"Moderate Match","Low Match"))),"") | AE11: =IF($D11="","",IF(OR($M11="Rejected",$M11="Withdrawn"),IF($AB11<>"",$AB11,IF(OR($M11="Rejected",ISNUMBER($C11)),"Applied","Wishlist")),IF($M11="",IF(ISNUMBER($C11),"Applied","Wishlist"),$M11))) | AF11: =IF(AND(ISNUMBER($C11),ISNUMBER($AA11)),$AA11-$C11,"") | AG11: =IF($AE11="","",IFERROR(MATCH($AE11,{"Wishlist","Applied","Screening","Interview 1","Interview 2","Final","Offer","Accepted"},0)-1,"")) | AH11: =IF($AC11="","",MATCH($AC11,{"FOLLOW UP REQUIRED","ACTION DUE TODAY","NO RESPONSE","DUE SOON"},0)*100000+IF(ISNUMBER($O11),$O11,IF(ISNUMBER($C11),$C11,0))+ROW()/10000) | AI11: =IF(AND(ISNUMBER($AG11),$AG11>=1,$AG11<=6,$M11<>"Rejected",$M11<>"Withdrawn"),(10-$AG11)*100000+IF(ISNUMBER($C11),$C11,0)+ROW()/10000,"")
AC12: =IF(OR($D12="",$M12="Rejected",$M12="Withdrawn",$M12="Accepted"),"",IF(ISNUMBER($O12),IF(INT($O12)<TODAY(),"FOLLOW UP REQUIRED",IF(INT($O12)=TODAY(),"ACTION DUE TODAY",IF(INT($O12)-TODAY()<=Set_DueSoonDays,"DUE SOON",""))),IF(AND($M12="Applied",$AA12=""),IF(ISNUMBER($C12),IF(TODAY()-$C12>=Set_FollowUpDays,"NO RESPONSE",""),""),""))) | AD12: =IF(ISNUMBER($L12),IF($L12>=90,"Excellent Match",IF($L12>=75,"Strong Match",IF($L12>=60,"Moderate Match","Low Match"))),"") | AE12: =IF($D12="","",IF(OR($M12="Rejected",$M12="Withdrawn"),IF($AB12<>"",$AB12,IF(OR($M12="Rejected",ISNUMBER($C12)),"Applied","Wishlist")),IF($M12="",IF(ISNUMBER($C12),"Applied","Wishlist"),$M12))) | AF12: =IF(AND(ISNUMBER($C12),ISNUMBER($AA12)),$AA12-$C12,"") | AG12: =IF($AE12="","",IFERROR(MATCH($AE12,{"Wishlist","Applied","Screening","Interview 1","Interview 2","Final","Offer","Accepted"},0)-1,"")) | AH12: =IF($AC12="","",MATCH($AC12,{"FOLLOW UP REQUIRED","ACTION DUE TODAY","NO RESPONSE","DUE SOON"},0)*100000+IF(ISNUMBER($O12),$O12,IF(ISNUMBER($C12),$C12,0))+ROW()/10000) | AI12: =IF(AND(ISNUMBER($AG12),$AG12>=1,$AG12<=6,$M12<>"Rejected",$M12<>"Withdrawn"),(10-$AG12)*100000+IF(ISNUMBER($C12),$C12,0)+ROW()/10000,"")
AC13: =IF(OR($D13="",$M13="Rejected",$M13="Withdrawn",$M13="Accepted"),"",IF(ISNUMBER($O13),IF(INT($O13)<TODAY(),"FOLLOW UP REQUIRED",IF(INT($O13)=TODAY(),"ACTION DUE TODAY",IF(INT($O13)-TODAY()<=Set_DueSoonDays,"DUE SOON",""))),IF(AND($M13="Applied",$AA13=""),IF(ISNUMBER($C13),IF(TODAY()-$C13>=Set_FollowUpDays,"NO RESPONSE",""),""),""))) | AD13: =IF(ISNUMBER($L13),IF($L13>=90,"Excellent Match",IF($L13>=75,"Strong Match",IF($L13>=60,"Moderate Match","Low Match"))),"") | AE13: =IF($D13="","",IF(OR($M13="Rejected",$M13="Withdrawn"),IF($AB13<>"",$AB13,IF(OR($M13="Rejected",ISNUMBER($C13)),"Applied","Wishlist")),IF($M13="",IF(ISNUMBER($C13),"Applied","Wishlist"),$M13))) | AF13: =IF(AND(ISNUMBER($C13),ISNUMBER($AA13)),$AA13-$C13,"") | AG13: =IF($AE13="","",IFERROR(MATCH($AE13,{"Wishlist","Applied","Screening","Interview 1","Interview 2","Final","Offer","Accepted"},0)-1,"")) | AH13: =IF($AC13="","",MATCH($AC13,{"FOLLOW UP REQUIRED","ACTION DUE TODAY","NO RESPONSE","DUE SOON"},0)*100000+IF(ISNUMBER($O13),$O13,IF(ISNUMBER($C13),$C13,0))+ROW()/10000) | AI13: =IF(AND(ISNUMBER($AG13),$AG13>=1,$AG13<=6,$M13<>"Rejected",$M13<>"Withdrawn"),(10-$AG13)*100000+IF(ISNUMBER($C13),$C13,0)+ROW()/10000,"")
AC14: =IF(OR($D14="",$M14="Rejected",$M14="Withdrawn",$M14="Accepted"),"",IF(ISNUMBER($O14),IF(INT($O14)<TODAY(),"FOLLOW UP REQUIRED",IF(INT($O14)=TODAY(),"ACTION DUE TODAY",IF(INT($O14)-TODAY()<=Set_DueSoonDays,"DUE SOON",""))),IF(AND($M14="Applied",$AA14=""),IF(ISNUMBER($C14),IF(TODAY()-$C14>=Set_FollowUpDays,"NO RESPONSE",""),""),""))) | AD14: =IF(ISNUMBER($L14),IF($L14>=90,"Excellent Match",IF($L14>=75,"Strong Match",IF($L14>=60,"Moderate Match","Low Match"))),"") | AE14: =IF($D14="","",IF(OR($M14="Rejected",$M14="Withdrawn"),IF($AB14<>"",$AB14,IF(OR($M14="Rejected",ISNUMBER($C14)),"Applied","Wishlist")),IF($M14="",IF(ISNUMBER($C14),"Applied","Wishlist"),$M14))) | AF14: =IF(AND(ISNUMBER($C14),ISNUMBER($AA14)),$AA14-$C14,"") | AG14: =IF($AE14="","",IFERROR(MATCH($AE14,{"Wishlist","Applied","Screening","Interview 1","Interview 2","Final","Offer","Accepted"},0)-1,"")) | AH14: =IF($AC14="","",MATCH($AC14,{"FOLLOW UP REQUIRED","ACTION DUE TODAY","NO RESPONSE","DUE SOON"},0)*100000+IF(ISNUMBER($O14),$O14,IF(ISNUMBER($C14),$C14,0))+ROW()/10000) | AI14: =IF(AND(ISNUMBER($AG14),$AG14>=1,$AG14<=6,$M14<>"Rejected",$M14<>"Withdrawn"),(10-$AG14)*100000+IF(ISNUMBER($C14),$C14,0)+ROW()/10000,"")
AC15: =IF(OR($D15="",$M15="Rejected",$M15="Withdrawn",$M15="Accepted"),"",IF(ISNUMBER($O15),IF(INT($O15)<TODAY(),"FOLLOW UP REQUIRED",IF(INT($O15)=TODAY(),"ACTION DUE TODAY",IF(INT($O15)-TODAY()<=Set_DueSoonDays,"DUE SOON",""))),IF(AND($M15="Applied",$AA15=""),IF(ISNUMBER($C15),IF(TODAY()-$C15>=Set_FollowUpDays,"NO RESPONSE",""),""),""))) | AD15: =IF(ISNUMBER($L15),IF($L15>=90,"Excellent Match",IF($L15>=75,"Strong Match",IF($L15>=60,"Moderate Match","Low Match"))),"") | AE15: =IF($D15="","",IF(OR($M15="Rejected",$M15="Withdrawn"),IF($AB15<>"",$AB15,IF(OR($M15="Rejected",ISNUMBER($C15)),"Applied","Wishlist")),IF($M15="",IF(ISNUMBER($C15),"Applied","Wishlist"),$M15))) | AF15: =IF(AND(ISNUMBER($C15),ISNUMBER($AA15)),$AA15-$C15,"") | AG15: =IF($AE15="","",IFERROR(MATCH($AE15,{"Wishlist","Applied","Screening","Interview 1","Interview 2","Final","Offer","Accepted"},0)-1,"")) | AH15: =IF($AC15="","",MATCH($AC15,{"FOLLOW UP REQUIRED","ACTION DUE TODAY","NO RESPONSE","DUE SOON"},0)*100000+IF(ISNUMBER($O15),$O15,IF(ISNUMBER($C15),$C15,0))+ROW()/10000) | AI15: =IF(AND(ISNUMBER($AG15),$AG15>=1,$AG15<=6,$M15<>"Rejected",$M15<>"Withdrawn"),(10-$AG15)*100000+IF(ISNUMBER($C15),$C15,0)+ROW()/10000,"")
AC16: =IF(OR($D16="",$M16="Rejected",$M16="Withdrawn",$M16="Accepted"),"",IF(ISNUMBER($O16),IF(INT($O16)<TODAY(),"FOLLOW UP REQUIRED",IF(INT($O16)=TODAY(),"ACTION DUE TODAY",IF(INT($O16)-TODAY()<=Set_DueSoonDays,"DUE SOON",""))),IF(AND($M16="Applied",$AA16=""),IF(ISNUMBER($C16),IF(TODAY()-$C16>=Set_FollowUpDays,"NO RESPONSE",""),""),""))) | AD16: =IF(ISNUMBER($L16),IF($L16>=90,"Excellent Match",IF($L16>=75,"Strong Match",IF($L16>=60,"Moderate Match","Low Match"))),"") | AE16: =IF($D16="","",IF(OR($M16="Rejected",$M16="Withdrawn"),IF($AB16<>"",$AB16,IF(OR($M16="Rejected",ISNUMBER($C16)),"Applied","Wishlist")),IF($M16="",IF(ISNUMBER($C16),"Applied","Wishlist"),$M16))) | AF16: =IF(AND(ISNUMBER($C16),ISNUMBER($AA16)),$AA16-$C16,"") | AG16: =IF($AE16="","",IFERROR(MATCH($AE16,{"Wishlist","Applied","Screening","Interview 1","Interview 2","Final","Offer","Accepted"},0)-1,"")) | AH16: =IF($AC16="","",MATCH($AC16,{"FOLLOW UP REQUIRED","ACTION DUE TODAY","NO RESPONSE","DUE SOON"},0)*100000+IF(ISNUMBER($O16),$O16,IF(ISNUMBER($C16),$C16,0))+ROW()/10000) | AI16: =IF(AND(ISNUMBER($AG16),$AG16>=1,$AG16<=6,$M16<>"Rejected",$M16<>"Withdrawn"),(10-$AG16)*100000+IF(ISNUMBER($C16),$C16,0)+ROW()/10000,"")
... AC1004: =IF(OR($D1004="",$M1004="Rejected",$M1004="Withdrawn",$M1004="Accepted"),"",IF(ISNUMBER($O1004),IF(INT($O1004)<TODAY(),"FOLLOW UP REQUIRED",IF(INT($O1004)=TODAY(),"ACTION DUE TODAY",IF(INT($O1004)-TODAY()<=Set_DueSoonDays,"DUE SOON",""))),IF(AND($M1004="Applied",$AA1004=""),IF(ISNUMBER($C1004),IF(TODAY()-$C1004>=Set_FollowUpDays,"NO RESPONSE",""),""),""))) | AD1004: =IF(ISNUMBER($L1004),IF($L1004>=90,"Excellent Match",IF($L1004>=75,"Strong Match",IF($L1004>=60,"Moderate Match","Low Match"))),"") | AE1004: =IF($D1004="","",IF(OR($M1004="Rejected",$M1004="Withdrawn"),IF($AB1004<>"",$AB1004,IF(OR($M1004="Rejected",ISNUMBER($C1004)),"Applied","Wishlist")),IF($M1004="",IF(ISNUMBER($C1004),"Applied","Wishlist"),$M1004))) | AF1004: =IF(AND(ISNUMBER($C1004),ISNUMBER($AA1004)),$AA1004-$C1004,"") | AG1004: =IF($AE1004="","",IFERROR(MATCH($AE1004,{"Wishlist","Applied","Screening","Interview 1","Interview 2","Final","Offer","Accepted"},0)-1,"")) | AH1004: =IF($AC1004="","",MATCH($AC1004,{"FOLLOW UP REQUIRED","ACTION DUE TODAY","NO RESPONSE","DUE SOON"},0)*100000+IF(ISNUMBER($O1004),$O1004,IF(ISNUMBER($C1004),$C1004,0))+ROW()/10000) | AI1004: =IF(AND(ISNUMBER($AG1004),$AG1004>=1,$AG1004<=6,$M1004<>"Rejected",$M1004<>"Withdrawn"),(10-$AG1004)*100000+IF(ISNUMBER($C1004),$C1004,0)+ROW()/10000,"")

Sheet Interviews
A1: Interviews | O1: Due-soon days
A2: One row per interview round — preparation, performance and what happens next. | O2: =Set_DueSoonDays
A3: Interviews in the next few days are highlighted; 'Not Started' prep turns red when the interview is close.
A4: Company | B4: Job Title | C4: Interview Stage | D4: Interview Date | E4: Interviewer | F4: Interview Type | G4: Preparation Status | H4: Key Topics | I4: Questions to Ask | J4: My Performance | K4: Feedback | L4: Next Step | M4: Next Step Date | N4: Notes | O4: Upcoming Key (helper)
O5: =IF(AND($A5<>"",ISNUMBER($D5)),IF(AND(INT($D5)>=TODAY(),INT($D5)-TODAY()<=Set_InterviewWindow),$D5+ROW()/100000,""),"")
O6: =IF(AND($A6<>"",ISNUMBER($D6)),IF(AND(INT($D6)>=TODAY(),INT($D6)-TODAY()<=Set_InterviewWindow),$D6+ROW()/100000,""),"")
O7: =IF(AND($A7<>"",ISNUMBER($D7)),IF(AND(INT($D7)>=TODAY(),INT($D7)-TODAY()<=Set_InterviewWindow),$D7+ROW()/100000,""),"")
O8: =IF(AND($A8<>"",ISNUMBER($D8)),IF(AND(INT($D8)>=TODAY(),INT($D8)-TODAY()<=Set_InterviewWindow),$D8+ROW()/100000,""),"")
O9: =IF(AND($A9<>"",ISNUMBER($D9)),IF(AND(INT($D9)>=TODAY(),INT($D9)-TODAY()<=Set_InterviewWindow),$D9+ROW()/100000,""),"")
O10: =IF(AND($A10<>"",ISNUMBER($D10)),IF(AND(INT($D10)>=TODAY(),INT($D10)-TODAY()<=Set_InterviewWindow),$D10+ROW()/100000,""),"")
O11: =IF(AND($A11<>"",ISNUMBER($D11)),IF(AND(INT($D11)>=TODAY(),INT($D11)-TODAY()<=Set_InterviewWindow),$D11+ROW()/100000,""),"")
O12: =IF(AND($A12<>"",ISNUMBER($D12)),IF(AND(INT($D12)>=TODAY(),INT($D12)-TODAY()<=Set_InterviewWindow),$D12+ROW()/100000,""),"")
O13: =IF(AND($A13<>"",ISNUMBER($D13)),IF(AND(INT($D13)>=TODAY(),INT($D13)-TODAY()<=Set_InterviewWindow),$D13+ROW()/100000,""),"")
O14: =IF(AND($A14<>"",ISNUMBER($D14)),IF(AND(INT($D14)>=TODAY(),INT($D14)-TODAY()<=Set_InterviewWindow),$D14+ROW()/100000,""),"")
O15: =IF(AND($A15<>"",ISNUMBER($D15)),IF(AND(INT($D15)>=TODAY(),INT($D15)-TODAY()<=Set_InterviewWindow),$D15+ROW()/100000,""),"")
O16: =IF(AND($A16<>"",ISNUMBER($D16)),IF(AND(INT($D16)>=TODAY(),INT($D16)-TODAY()<=Set_InterviewWindow),$D16+ROW()/100000,""),"")
... O304: =IF(AND($A304<>"",ISNUMBER($D304)),IF(AND(INT($D304)>=TODAY(),INT($D304)-TODAY()<=Set_InterviewWindow),$D304+ROW()/100000,""),"")

Sheet Companies
A1: Companies
A2: Target companies — worth tracking even when there's no perfect opening yet.
A3: Use the same company spelling as on Applications and Contacts so the counts on the right link up. | M3: AUTO-CALCULATED ▸ from Applications & Contacts
A4: Company | B4: Industry | C4: Location | D4: AI Relevance | E4: Target Role | F4: Careers URL | G4: Contact | H4: Contact LinkedIn | I4: Referral | J4: Priority | K4: Status | L4: Notes | M4: Applications | N4: Active Applications | O4: Contacts
M5: =IF($A5="","",COUNTIFS(App_Company,$A5,App_Stage,">=1")) | N5: =IF($A5="","",COUNTIFS(App_Company,$A5,App_ActiveKey,">0")) | O5: =IF($A5="","",COUNTIF(Ct_Company,$A5))
M6: =IF($A6="","",COUNTIFS(App_Company,$A6,App_Stage,">=1")) | N6: =IF($A6="","",COUNTIFS(App_Company,$A6,App_ActiveKey,">0")) | O6: =IF($A6="","",COUNTIF(Ct_Company,$A6))
M7: =IF($A7="","",COUNTIFS(App_Company,$A7,App_Stage,">=1")) | N7: =IF($A7="","",COUNTIFS(App_Company,$A7,App_ActiveKey,">0")) | O7: =IF($A7="","",COUNTIF(Ct_Company,$A7))
M8: =IF($A8="","",COUNTIFS(App_Company,$A8,App_Stage,">=1")) | N8: =IF($A8="","",COUNTIFS(App_Company,$A8,App_ActiveKey,">0")) | O8: =IF($A8="","",COUNTIF(Ct_Company,$A8))
M9: =IF($A9="","",COUNTIFS(App_Company,$A9,App_Stage,">=1")) | N9: =IF($A9="","",COUNTIFS(App_Company,$A9,App_ActiveKey,">0")) | O9: =IF($A9="","",COUNTIF(Ct_Company,$A9))
M10: =IF($A10="","",COUNTIFS(App_Company,$A10,App_Stage,">=1")) | N10: =IF($A10="","",COUNTIFS(App_Company,$A10,App_ActiveKey,">0")) | O10: =IF($A10="","",COUNTIF(Ct_Company,$A10))
